2018-12-03 18:46:07,808 ERROR: Exception on / [GET] [in /home/aleksey/pythonvenv/flask-env/lib/python3.6/site-packages/flask/app.py:1761
Traceback (most recent call last):
  File "/home/aleksey/pythonvenv/flask-env/lib/python3.6/site-packages/flask/app.py", line 1813, in full_dispatch_request
    rv = self.dispatch_request()
  File "/home/aleksey/pythonvenv/flask-env/lib/python3.6/site-packages/flask/app.py", line 1791, in dispatch_request
    self.raise_routing_exception(req)
  File "/home/aleksey/pythonvenv/flask-env/lib/python3.6/site-packages/flask/app.py", line 1774, in raise_routing_exception
    raise request.routing_exception
  File "/home/aleksey/pythonvenv/flask-env/lib/python3.6/site-packages/flask/ctx.py", line 336, in match_request
    self.url_adapter.match(return_rule=True)
  File "/home/aleksey/pythonvenv/flask-env/lib/python3.6/site-packages/werkzeug/routing.py", line 1581, in match
    raise NotFound()
werkzeug.exceptions.NotFound: 404 Not Found: The requested URL was not found on the server.  If you entered the URL manually please check your spelling and try again.

During handling of the above exception, another exception occurred:

Traceback (most recent call last):
  File "/home/aleksey/pythonvenv/flask-env/lib/python3.6/site-packages/sqlalchemy/engine/base.py", line 1193, in _execute_context
    context)
  File "/home/aleksey/pythonvenv/flask-env/lib/python3.6/site-packages/sqlalchemy/engine/default.py", line 509, in do_execute
    cursor.execute(statement, parameters)
sqlite3.OperationalError: no such table: user

The above exception was the direct cause of the following exception:

Traceback (most recent call last):
  File "/home/aleksey/pythonvenv/flask-env/lib/python3.6/site-packages/flask/app.py", line 2292, in wsgi_app
    response = self.full_dispatch_request()
  File "/home/aleksey/pythonvenv/flask-env/lib/python3.6/site-packages/flask/app.py", line 1815, in full_dispatch_request
    rv = self.handle_user_exception(e)
  File "/home/aleksey/pythonvenv/flask-env/lib/python3.6/site-packages/flask/app.py", line 1713, in handle_user_exception
    return self.handle_http_exception(e)
  File "/home/aleksey/pythonvenv/flask-env/lib/python3.6/site-packages/flask/app.py", line 1644, in handle_http_exception
    return handler(e)
  File "/home/aleksey/Документы/project/app/errors/handlers.py", line 7, in not_found_error
    return render_template('errors/404.html'), 404
  File "/home/aleksey/pythonvenv/flask-env/lib/python3.6/site-packages/flask/templating.py", line 133, in render_template
    ctx.app.update_template_context(context)
  File "/home/aleksey/pythonvenv/flask-env/lib/python3.6/site-packages/flask/app.py", line 792, in update_template_context
    context.update(func())
  File "/home/aleksey/pythonvenv/flask-env/lib/python3.6/site-packages/flask_login/utils.py", line 368, in _user_context_processor
    return dict(current_user=_get_user())
  File "/home/aleksey/pythonvenv/flask-env/lib/python3.6/site-packages/flask_login/utils.py", line 335, in _get_user
    current_app.login_manager._load_user()
  File "/home/aleksey/pythonvenv/flask-env/lib/python3.6/site-packages/flask_login/login_manager.py", line 359, in _load_user
    return self.reload_user()
  File "/home/aleksey/pythonvenv/flask-env/lib/python3.6/site-packages/flask_login/login_manager.py", line 321, in reload_user
    user = self.user_callback(user_id)
  File "/home/aleksey/Документы/project/app/models.py", line 94, in load_user
    return User.query.get(int(id))
  File "/home/aleksey/pythonvenv/flask-env/lib/python3.6/site-packages/sqlalchemy/orm/query.py", line 924, in get
    ident, loading.load_on_pk_identity)
  File "/home/aleksey/pythonvenv/flask-env/lib/python3.6/site-packages/sqlalchemy/orm/query.py", line 1007, in _get_impl
    return db_load_fn(self, primary_key_identity)
  File "/home/aleksey/pythonvenv/flask-env/lib/python3.6/site-packages/sqlalchemy/orm/loading.py", line 250, in load_on_pk_identity
    return q.one()
  File "/home/aleksey/pythonvenv/flask-env/lib/python3.6/site-packages/sqlalchemy/orm/query.py", line 2954, in one
    ret = self.one_or_none()
  File "/home/aleksey/pythonvenv/flask-env/lib/python3.6/site-packages/sqlalchemy/orm/query.py", line 2924, in one_or_none
    ret = list(self)
  File "/home/aleksey/pythonvenv/flask-env/lib/python3.6/site-packages/sqlalchemy/orm/query.py", line 2995, in __iter__
    return self._execute_and_instances(context)
  File "/home/aleksey/pythonvenv/flask-env/lib/python3.6/site-packages/sqlalchemy/orm/query.py", line 3018, in _execute_and_instances
    result = conn.execute(querycontext.statement, self._params)
  File "/home/aleksey/pythonvenv/flask-env/lib/python3.6/site-packages/sqlalchemy/engine/base.py", line 948, in execute
    return meth(self, multiparams, params)
  File "/home/aleksey/pythonvenv/flask-env/lib/python3.6/site-packages/sqlalchemy/sql/elements.py", line 269, in _execute_on_connection
    return connection._execute_clauseelement(self, multiparams, params)
  File "/home/aleksey/pythonvenv/flask-env/lib/python3.6/site-packages/sqlalchemy/engine/base.py", line 1060, in _execute_clauseelement
    compiled_sql, distilled_params
  File "/home/aleksey/pythonvenv/flask-env/lib/python3.6/site-packages/sqlalchemy/engine/base.py", line 1200, in _execute_context
    context)
  File "/home/aleksey/pythonvenv/flask-env/lib/python3.6/site-packages/sqlalchemy/engine/base.py", line 1413, in _handle_dbapi_exception
    exc_info
  File "/home/aleksey/pythonvenv/flask-env/lib/python3.6/site-packages/sqlalchemy/util/compat.py", line 265, in raise_from_cause
    reraise(type(exception), exception, tb=exc_tb, cause=cause)
  File "/home/aleksey/pythonvenv/flask-env/lib/python3.6/site-packages/sqlalchemy/util/compat.py", line 248, in reraise
    raise value.with_traceback(tb)
  File "/home/aleksey/pythonvenv/flask-env/lib/python3.6/site-packages/sqlalchemy/engine/base.py", line 1193, in _execute_context
    context)
  File "/home/aleksey/pythonvenv/flask-env/lib/python3.6/site-packages/sqlalchemy/engine/default.py", line 509, in do_execute
    cursor.execute(statement, parameters)
sqlalchemy.exc.OperationalError: (sqlite3.OperationalError) no such table: user [SQL: 'SELECT user.id AS user_id, user.username AS user_username, user.email AS user_email, user.password_hash AS user_password_hash, user.about_me AS user_about_me, user.last_seen AS user_last_seen \nFROM user \nWHERE user.id = ?'] [parameters: (1,)] (Background on this error at: http://sqlalche.me/e/e3q8)
